2020-12-18 20:38:15,621 ERROR: Exception on /reset_password_request [POST] [in /home/mahmoudodeh/Desktop/Flask/flask-venv/lib/python3.8/site-packages/flask/app.py:1891]
Traceback (most recent call last):
  File "/home/mahmoudodeh/Desktop/Flask/flask-venv/lib/python3.8/site-packages/flask/app.py", line 2447, in wsgi_app
    response = self.full_dispatch_request()
  File "/home/mahmoudodeh/Desktop/Flask/flask-venv/lib/python3.8/site-packages/flask/app.py", line 1952, in full_dispatch_request
    rv = self.handle_user_exception(e)
  File "/home/mahmoudodeh/Desktop/Flask/flask-venv/lib/python3.8/site-packages/flask/app.py", line 1821, in handle_user_exception
    reraise(exc_type, exc_value, tb)
  File "/home/mahmoudodeh/Desktop/Flask/flask-venv/lib/python3.8/site-packages/flask/_compat.py", line 39, in reraise
    raise value
  File "/home/mahmoudodeh/Desktop/Flask/flask-venv/lib/python3.8/site-packages/flask/app.py", line 1950, in full_dispatch_request
    rv = self.dispatch_request()
  File "/home/mahmoudodeh/Desktop/Flask/flask-venv/lib/python3.8/site-packages/flask/app.py", line 1936, in dispatch_request
    return self.view_functions[rule.endpoint](**req.view_args)
  File "/home/mahmoudodeh/Desktop/Flask/Flask-Tutorial/microblog/app/routes.py", line 182, in reset_password_request
    send_password_reset_email(user)
  File "/home/mahmoudodeh/Desktop/Flask/Flask-Tutorial/microblog/app/email.py", line 37, in send_password_reset_email
    send_email('[Microblog] Reset Your Password',
  File "/home/mahmoudodeh/Desktop/Flask/Flask-Tutorial/microblog/app/email.py", line 18, in send_email
    server.login(sender_email,password)
  File "/usr/lib/python3.8/smtplib.py", line 734, in login
    raise last_exception
  File "/usr/lib/python3.8/smtplib.py", line 723, in login
    (code, resp) = self.auth(
  File "/usr/lib/python3.8/smtplib.py", line 646, in auth
    raise SMTPAuthenticationError(code, resp)
smtplib.SMTPAuthenticationError: (535, b'5.7.8 Username and Password not accepted. Learn more at\n5.7.8  https://support.google.com/mail/?p=BadCredentials s25sm16648799wrs.49 - gsmtp')
2020-12-20 08:29:55,779 INFO: Microblog startup [in /home/mahmoudodeh/Desktop/Flask/Flask-Tutorial/microblog/app/__init__.py:52]
2020-12-20 08:34:20,698 INFO: Microblog startup [in /home/mahmoudodeh/Desktop/Flask/Flask-Tutorial/microblog/app/__init__.py:52]
2020-12-20 08:36:55,897 INFO: Microblog startup [in /home/mahmoudodeh/Desktop/Flask/Flask-Tutorial/microblog/app/__init__.py:52]
2020-12-20 08:37:26,715 INFO: Microblog startup [in /home/mahmoudodeh/Desktop/Flask/Flask-Tutorial/microblog/app/__init__.py:52]
2020-12-20 08:38:44,581 INFO: Microblog startup [in /home/mahmoudodeh/Desktop/Flask/Flask-Tutorial/microblog/app/__init__.py:52]
2020-12-20 08:39:53,162 INFO: Microblog startup [in /home/mahmoudodeh/Desktop/Flask/Flask-Tutorial/microblog/app/__init__.py:52]
2020-12-20 08:42:32,972 INFO: Microblog startup [in /home/mahmoudodeh/Desktop/Flask/Flask-Tutorial/microblog/app/__init__.py:52]
2020-12-20 08:44:50,785 INFO: Microblog startup [in /home/mahmoudodeh/Desktop/Flask/Flask-Tutorial/microblog/app/__init__.py:52]
2020-12-20 08:44:52,730 ERROR: Exception on /login [GET] [in /home/mahmoudodeh/Desktop/Flask/flask-venv/lib/python3.8/site-packages/flask/app.py:1891]
Traceback (most recent call last):
  File "/home/mahmoudodeh/Desktop/Flask/flask-venv/lib/python3.8/site-packages/flask/app.py", line 2447, in wsgi_app
    response = self.full_dispatch_request()
  File "/home/mahmoudodeh/Desktop/Flask/flask-venv/lib/python3.8/site-packages/flask/app.py", line 1952, in full_dispatch_request
    rv = self.handle_user_exception(e)
  File "/home/mahmoudodeh/Desktop/Flask/flask-venv/lib/python3.8/site-packages/flask/app.py", line 1821, in handle_user_exception
    reraise(exc_type, exc_value, tb)
  File "/home/mahmoudodeh/Desktop/Flask/flask-venv/lib/python3.8/site-packages/flask/_compat.py", line 39, in reraise
    raise value
  File "/home/mahmoudodeh/Desktop/Flask/flask-venv/lib/python3.8/site-packages/flask/app.py", line 1950, in full_dispatch_request
    rv = self.dispatch_request()
  File "/home/mahmoudodeh/Desktop/Flask/flask-venv/lib/python3.8/site-packages/flask/app.py", line 1936, in dispatch_request
    return self.view_functions[rule.endpoint](**req.view_args)
  File "/home/mahmoudodeh/Desktop/Flask/Flask-Tutorial/microblog/app/routes.py", line 69, in login
    return render_template('login.html', title='Sign In', form=form)
  File "/home/mahmoudodeh/Desktop/Flask/flask-venv/lib/python3.8/site-packages/flask/templating.py", line 138, in render_template
    ctx.app.jinja_env.get_or_select_template(template_name_or_list),
  File "/home/mahmoudodeh/Desktop/Flask/flask-venv/lib/python3.8/site-packages/jinja2/environment.py", line 930, in get_or_select_template
    return self.get_template(template_name_or_list, parent, globals)
  File "/home/mahmoudodeh/Desktop/Flask/flask-venv/lib/python3.8/site-packages/jinja2/environment.py", line 883, in get_template
    return self._load_template(name, self.make_globals(globals))
  File "/home/mahmoudodeh/Desktop/Flask/flask-venv/lib/python3.8/site-packages/jinja2/environment.py", line 857, in _load_template
    template = self.loader.load(self, name, globals)
  File "/home/mahmoudodeh/Desktop/Flask/flask-venv/lib/python3.8/site-packages/jinja2/loaders.py", line 127, in load
    code = environment.compile(source, name, filename)
  File "/home/mahmoudodeh/Desktop/Flask/flask-venv/lib/python3.8/site-packages/jinja2/environment.py", line 638, in compile
    self.handle_exception(source=source_hint)
  File "/home/mahmoudodeh/Desktop/Flask/flask-venv/lib/python3.8/site-packages/jinja2/environment.py", line 832, in handle_exception
    reraise(*rewrite_traceback_stack(source=source))
  File "/home/mahmoudodeh/Desktop/Flask/flask-venv/lib/python3.8/site-packages/jinja2/_compat.py", line 28, in reraise
    raise value.with_traceback(tb)
  File "/home/mahmoudodeh/Desktop/Flask/Flask-Tutorial/microblog/app/templates/login.html", line 22, in template
    {% block app_content %}
jinja2.exceptions.TemplateAssertionError: block 'app_content' defined twice
2020-12-20 08:44:53,606 ERROR: Exception on /login [GET] [in /home/mahmoudodeh/Desktop/Flask/flask-venv/lib/python3.8/site-packages/flask/app.py:1891]
Traceback (most recent call last):
  File "/home/mahmoudodeh/Desktop/Flask/flask-venv/lib/python3.8/site-packages/flask/app.py", line 2447, in wsgi_app
    response = self.full_dispatch_request()
  File "/home/mahmoudodeh/Desktop/Flask/flask-venv/lib/python3.8/site-packages/flask/app.py", line 1952, in full_dispatch_request
    rv = self.handle_user_exception(e)
  File "/home/mahmoudodeh/Desktop/Flask/flask-venv/lib/python3.8/site-packages/flask/app.py", line 1821, in handle_user_exception
    reraise(exc_type, exc_value, tb)
  File "/home/mahmoudodeh/Desktop/Flask/flask-venv/lib/python3.8/site-packages/flask/_compat.py", line 39, in reraise
    raise value
  File "/home/mahmoudodeh/Desktop/Flask/flask-venv/lib/python3.8/site-packages/flask/app.py", line 1950, in full_dispatch_request
    rv = self.dispatch_request()
  File "/home/mahmoudodeh/Desktop/Flask/flask-venv/lib/python3.8/site-packages/flask/app.py", line 1936, in dispatch_request
    return self.view_functions[rule.endpoint](**req.view_args)
  File "/home/mahmoudodeh/Desktop/Flask/Flask-Tutorial/microblog/app/routes.py", line 69, in login
    return render_template('login.html', title='Sign In', form=form)
  File "/home/mahmoudodeh/Desktop/Flask/flask-venv/lib/python3.8/site-packages/flask/templating.py", line 138, in render_template
    ctx.app.jinja_env.get_or_select_template(template_name_or_list),
  File "/home/mahmoudodeh/Desktop/Flask/flask-venv/lib/python3.8/site-packages/jinja2/environment.py", line 930, in get_or_select_template
    return self.get_template(template_name_or_list, parent, globals)
  File "/home/mahmoudodeh/Desktop/Flask/flask-venv/lib/python3.8/site-packages/jinja2/environment.py", line 883, in get_template
    return self._load_template(name, self.make_globals(globals))
  File "/home/mahmoudodeh/Desktop/Flask/flask-venv/lib/python3.8/site-packages/jinja2/environment.py", line 857, in _load_template
    template = self.loader.load(self, name, globals)
  File "/home/mahmoudodeh/Desktop/Flask/flask-venv/lib/python3.8/site-packages/jinja2/loaders.py", line 127, in load
    code = environment.compile(source, name, filename)
  File "/home/mahmoudodeh/Desktop/Flask/flask-venv/lib/python3.8/site-packages/jinja2/environment.py", line 638, in compile
    self.handle_exception(source=source_hint)
  File "/home/mahmoudodeh/Desktop/Flask/flask-venv/lib/python3.8/site-packages/jinja2/environment.py", line 832, in handle_exception
    reraise(*rewrite_traceback_stack(source=source))
  File "/home/mahmoudodeh/Desktop/Flask/flask-venv/lib/python3.8/site-packages/jinja2/_compat.py", line 28, in reraise
    raise value.with_traceback(tb)
  File "/home/mahmoudodeh/Desktop/Flask/Flask-Tutorial/microblog/app/templates/login.html", line 22, in template
    {% block app_content %}
jinja2.exceptions.TemplateAssertionError: block 'app_content' defined twice
